<?xml version="1.0" encoding="utf-8"?>
<!-- This URDF was automatically created by SolidWorks to URDF Exporter! Originally created by Stephen Brawner (brawner@gmail.com) 
     Commit Version: 1.6.0-4-g7f85cfe  Build Version: 1.6.7995.38578
     For more information, please see http://wiki.ros.org/sw_urdf_exporter -->
<robot
  name="SMART NS 12-1,85_ARTICOLATO.SLDASM">
  <link
    name="LinkBase">
    <inertial>
      <origin
        xyz="0.0744476654482306 0.115913824172212 0.0010678170884798"
        rpy="0 0 0" />
      <mass
        value="49.7889558845622" />
      <inertia
        ixx="0.87523928869254"
        ixy="0.0450449821195637"
        ixz="0.0221675978946128"
        iyy="2.13115026033701"
        iyz="-0.0128402770154969"
        izz="1.73800152420485" />
    </inertial>
    <visual>
      <origin
        xyz="0 0 0"
        rpy="0 0 0" />
      <geometry>
        <mesh
          filename="package://SMART NS 12-1,85_ARTICOLATO.SLDASM/meshes/LinkBase.STL" />
      </geometry>
      <material
        name="">
        <color
          rgba="1 0 0 1" />
      </material>
    </visual>
    <collision>
      <origin
        xyz="0 0 0"
        rpy="0 0 0" />
      <geometry>
        <mesh
          filename="package://SMART NS 12-1,85_ARTICOLATO.SLDASM/meshes/LinkBase.STL" />
      </geometry>
    </collision>
  </link>
  <link
    name="Link1">
    <inertial>
      <origin
        xyz="-0.106502056199313 0.202309935280237 1.7748990398715E-05"
        rpy="0 0 0" />
      <mass
        value="45.9345542594997" />
      <inertia
        ixx="0.558230706491936"
        ixy="0.140748891667565"
        ixz="-0.0150260133538752"
        iyy="1.0571184929808"
        iyz="0.0210703300466004"
        izz="0.996343838581334" />
    </inertial>
    <visual>
      <origin
        xyz="0 0 0"
        rpy="0 0 0" />
      <geometry>
        <mesh
          filename="package://SMART NS 12-1,85_ARTICOLATO.SLDASM/meshes/Link1.STL" />
      </geometry>
      <material
        name="">
        <color
          rgba="0.792156862745098 0.819607843137255 0.933333333333333 1" />
      </material>
    </visual>
    <collision>
      <origin
        xyz="0 0 0"
        rpy="0 0 0" />
      <geometry>
        <mesh
          filename="package://SMART NS 12-1,85_ARTICOLATO.SLDASM/meshes/Link1.STL" />
      </geometry>
    </collision>
  </link>
  <joint
    name="Ax1"
    type="continuous">
    <origin
      xyz="0 0 0.251"
      rpy="1.5708 0 0" />
    <parent
      link="LinkBase" />
    <child
      link="Link1" />
    <axis
      xyz="0 1 0" />
  </joint>
  <link
    name="Link2">
    <inertial>
      <origin
        xyz="0.0125874045135702 0.287861223589356 -0.10476726513625"
        rpy="0 0 0" />
      <mass
        value="7.51128820326683" />
      <inertia
        ixx="0.49847614415948"
        ixy="-0.00984951243183954"
        ixz="0.00318186428508749"
        iyy="0.0609511647723986"
        iyz="0.0500300030481755"
        izz="0.504104875138674" />
    </inertial>
    <visual>
      <origin
        xyz="0 0 0"
        rpy="0 0 0" />
      <geometry>
        <mesh
          filename="package://SMART NS 12-1,85_ARTICOLATO.SLDASM/meshes/Link2.STL" />
      </geometry>
      <material
        name="">
        <color
          rgba="1 0 0 1" />
      </material>
    </visual>
    <collision>
      <origin
        xyz="0 0 0"
        rpy="0 0 0" />
      <geometry>
        <mesh
          filename="package://SMART NS 12-1,85_ARTICOLATO.SLDASM/meshes/Link2.STL" />
      </geometry>
    </collision>
  </link>
  <joint
    name="Ax2"
    type="continuous">
    <origin
      xyz="-0.3 0.349 -0.101"
      rpy="0 0 -7.8035E-05" />
    <parent
      link="Link1" />
    <child
      link="Link2" />
    <axis
      xyz="0 0 1" />
  </joint>
  <link
    name="Link3">
    <inertial>
      <origin
        xyz="-0.0492113438257876 0.137646138939903 0.0901608936893595"
        rpy="0 0 0" />
      <mass
        value="21.7051384673217" />
      <inertia
        ixx="0.349281508240108"
        ixy="0.0493962728607473"
        ixz="0.0374156716422658"
        iyy="0.232073169225388"
        iyz="-0.0773152258110867"
        izz="0.305153657761036" />
    </inertial>
    <visual>
      <origin
        xyz="0 0 0"
        rpy="0 0 0" />
      <geometry>
        <mesh
          filename="package://SMART NS 12-1,85_ARTICOLATO.SLDASM/meshes/Link3.STL" />
      </geometry>
      <material
        name="">
        <color
          rgba="0.792156862745098 0.819607843137255 0.933333333333333 1" />
      </material>
    </visual>
    <collision>
      <origin
        xyz="0 0 0"
        rpy="0 0 0" />
      <geometry>
        <mesh
          filename="package://SMART NS 12-1,85_ARTICOLATO.SLDASM/meshes/Link3.STL" />
      </geometry>
    </collision>
  </link>
  <joint
    name="Ax3"
    type="continuous">
    <origin
      xyz="0 0.7 0"
      rpy="0 0 7.8035E-05" />
    <parent
      link="Link2" />
    <child
      link="Link3" />
    <axis
      xyz="0 0 1" />
  </joint>
  <link
    name="Link4">
    <inertial>
      <origin
        xyz="-0.415787044063144 -3.64732634383635E-06 -0.00842206225376062"
        rpy="0 0 0" />
      <mass
        value="5.72544149128189" />
      <inertia
        ixx="0.0230856306362713"
        ixy="7.37368732479341E-07"
        ixz="-0.000920611326172965"
        iyy="0.0669736432330281"
        iyz="4.08740356108042E-07"
        izz="0.0522796432807985" />
    </inertial>
    <visual>
      <origin
        xyz="0 0 0"
        rpy="0 0 0" />
      <geometry>
        <mesh
          filename="package://SMART NS 12-1,85_ARTICOLATO.SLDASM/meshes/Link4.STL" />
      </geometry>
      <material
        name="">
        <color
          rgba="0.792156862745098 0.819607843137255 0.933333333333333 1" />
      </material>
    </visual>
    <collision>
      <origin
        xyz="0 0 0"
        rpy="0 0 0" />
      <geometry>
        <mesh
          filename="package://SMART NS 12-1,85_ARTICOLATO.SLDASM/meshes/Link4.STL" />
      </geometry>
    </collision>
  </link>
  <joint
    name="Ax4"
    type="continuous">
    <origin
      xyz="-0.238 0.185 0.101"
      rpy="0 0 0" />
    <parent
      link="Link3" />
    <child
      link="Link4" />
    <axis
      xyz="1 0 0" />
  </joint>
  <link
    name="Link5">
    <inertial>
      <origin
        xyz="-0.0417593366580946 2.64366311861775E-05 -0.00106287342119625"
        rpy="0 0 0" />
      <mass
        value="0.559213536738551" />
      <inertia
        ixx="0.000416038661835265"
        ixy="-6.07198817068019E-07"
        ixz="2.00491794899905E-05"
        iyy="0.000988804723892516"
        iyz="5.3708654552333E-07"
        izz="0.000978864012499071" />
    </inertial>
    <visual>
      <origin
        xyz="0 0 0"
        rpy="0 0 0" />
      <geometry>
        <mesh
          filename="package://SMART NS 12-1,85_ARTICOLATO.SLDASM/meshes/Link5.STL" />
      </geometry>
      <material
        name="">
        <color
          rgba="0.501960784313725 0.501960784313725 0.501960784313725 1" />
      </material>
    </visual>
    <collision>
      <origin
        xyz="0 0 0"
        rpy="0 0 0" />
      <geometry>
        <mesh
          filename="package://SMART NS 12-1,85_ARTICOLATO.SLDASM/meshes/Link5.STL" />
      </geometry>
    </collision>
  </link>
  <joint
    name="Ax5"
    type="continuous">
    <origin
      xyz="-0.592 0 0"
      rpy="0 0 0.016135" />
    <parent
      link="Link4" />
    <child
      link="Link5" />
    <axis
      xyz="0 0 1" />
  </joint>
  <link
    name="LinkEE">
    <inertial>
      <origin
        xyz="-0.0163767177775365 -0.00130113388648864 3.25512854655319E-05"
        rpy="0 0 0" />
      <mass
        value="0.0919593711752515" />
      <inertia
        ixx="9.41339688883517E-05"
        ixy="3.24948856414075E-07"
        ixz="-3.55096500022067E-08"
        iyy="5.33523250768208E-05"
        iyz="-3.89486534784878E-09"
        izz="4.92478459379895E-05" />
    </inertial>
    <visual>
      <origin
        xyz="0 0 0"
        rpy="0 0 0" />
      <geometry>
        <mesh
          filename="package://SMART NS 12-1,85_ARTICOLATO.SLDASM/meshes/LinkEE.STL" />
      </geometry>
      <material
        name="">
        <color
          rgba="0.250980392156863 0.250980392156863 0.250980392156863 1" />
      </material>
    </visual>
    <collision>
      <origin
        xyz="0 0 0"
        rpy="0 0 0" />
      <geometry>
        <mesh
          filename="package://SMART NS 12-1,85_ARTICOLATO.SLDASM/meshes/LinkEE.STL" />
      </geometry>
    </collision>
  </link>
  <joint
    name="Ax6"
    type="continuous">
    <origin
      xyz="-0.092478 0 0"
      rpy="-1.5434 0 0" />
    <parent
      link="Link5" />
    <child
      link="LinkEE" />
    <axis
      xyz="1 0 0" />
  </joint>
</robot>