<?xml version="1.0" encoding="utf-8"?>
<!-- This URDF was automatically created by SolidWorks to URDF Exporter! Originally created by Stephen Brawner (brawner@gmail.com) 
     Commit Version: 1.6.0-4-g7f85cfe  Build Version: 1.6.7995.38578
     For more information, please see http://wiki.ros.org/sw_urdf_exporter -->
<robot
  name="SMART NS 12-1,85 ARC_040128.SLDASM">
  <link
    name="BaseLink">
    <inertial>
      <origin
        xyz="0.0744476654482305 0.115913824172212 0.00106781708847979"
        rpy="0 0 0" />
      <mass
        value="390.843303693814" />
      <inertia
        ixx="6.87062841623644"
        ixy="0.353603109638576"
        ixz="0.174015643472711"
        iyy="16.7295295436455"
        iyz="-0.100796174571651"
        izz="13.643311965008" />
    </inertial>
    <visual>
      <origin
        xyz="0 0 0"
        rpy="0 0 0" />
      <geometry>
        <mesh
          filename="package://SMART NS 12-1,85 ARC_040128.SLDASM/meshes/BaseLink.STL" />
      </geometry>
      <material
        name="">
        <color
          rgba="1 0 0 1" />
      </material>
    </visual>
    <collision>
      <origin
        xyz="0 0 0"
        rpy="0 0 0" />
      <geometry>
        <mesh
          filename="package://SMART NS 12-1,85 ARC_040128.SLDASM/meshes/BaseLink.STL" />
      </geometry>
    </collision>
  </link>
  <link
    name="Link1">
    <inertial>
      <origin
        xyz="-0.1065 0.20231 1.7749E-05"
        rpy="0 0 0" />
      <mass
        value="360.59" />
      <inertia
        ixx="4.3821"
        ixy="1.1049"
        ixz="-0.11795"
        iyy="8.2984"
        iyz="0.1654"
        izz="7.8213" />
    </inertial>
    <visual>
      <origin
        xyz="0 0 0"
        rpy="0 0 0" />
      <geometry>
        <mesh
          filename="package://SMART NS 12-1,85 ARC_040128.SLDASM/meshes/Link1.STL" />
      </geometry>
      <material
        name="">
        <color
          rgba="1 0 0 1" />
      </material>
    </visual>
    <collision>
      <origin
        xyz="0 0 0"
        rpy="0 0 0" />
      <geometry>
        <mesh
          filename="package://SMART NS 12-1,85 ARC_040128.SLDASM/meshes/Link1.STL" />
      </geometry>
    </collision>
  </link>
  <joint
    name="Ax1"
    type="continuous">
    <origin
      xyz="0 0 0.251"
      rpy="1.5708 0 0" />
    <parent
      link="BaseLink" />
    <child
      link="Link1" />
    <axis
      xyz="0 1 0" />
  </joint>
  <link
    name="Link2">
    <inertial>
      <origin
        xyz="0.012587 0.28786 -0.10477"
        rpy="0 0 0" />
      <mass
        value="58.964" />
      <inertia
        ixx="3.913"
        ixy="-0.077319"
        ixz="0.024977"
        iyy="0.47847"
        iyz="0.39274"
        izz="3.9572" />
    </inertial>
    <visual>
      <origin
        xyz="0 0 0"
        rpy="0 0 0" />
      <geometry>
        <mesh
          filename="package://SMART NS 12-1,85 ARC_040128.SLDASM/meshes/Link2.STL" />
      </geometry>
      <material
        name="">
        <color
          rgba="1 0 0 1" />
      </material>
    </visual>
    <collision>
      <origin
        xyz="0 0 0"
        rpy="0 0 0" />
      <geometry>
        <mesh
          filename="package://SMART NS 12-1,85 ARC_040128.SLDASM/meshes/Link2.STL" />
      </geometry>
    </collision>
  </link>
  <joint
    name="Ax2"
    type="continuous">
    <origin
      xyz="-0.3 0.349 -0.101"
      rpy="0 0 0" />
    <parent
      link="Link1" />
    <child
      link="Link2" />
    <axis
      xyz="0 0 1" />
  </joint>
  <link
    name="Link3">
    <inertial>
      <origin
        xyz="-0.0492113438257874 0.137646138939902 0.0901608936893602"
        rpy="0 0 0" />
      <mass
        value="170.385336968475" />
      <inertia
        ixx="2.74185983968485"
        ixy="0.387760741956867"
        ixz="0.293713022391787"
        iyy="1.82177437841929"
        iyz="-0.606924522617031"
        izz="2.39545621342414" />
    </inertial>
    <visual>
      <origin
        xyz="0 0 0"
        rpy="0 0 0" />
      <geometry>
        <mesh
          filename="package://SMART NS 12-1,85 ARC_040128.SLDASM/meshes/Link3.STL" />
      </geometry>
      <material
        name="">
        <color
          rgba="1 0 0 1" />
      </material>
    </visual>
    <collision>
      <origin
        xyz="0 0 0"
        rpy="0 0 0" />
      <geometry>
        <mesh
          filename="package://SMART NS 12-1,85 ARC_040128.SLDASM/meshes/Link3.STL" />
      </geometry>
    </collision>
  </link>
  <joint
    name="Ax3"
    type="continuous">
    <origin
      xyz="0 0.7 0"
      rpy="0 0 0" />
    <parent
      link="Link2" />
    <child
      link="Link3" />
    <axis
      xyz="0 0 1" />
  </joint>
  <link
    name="Link4">
    <inertial>
      <origin
        xyz="-0.41579 -3.6473E-06 -0.0084221"
        rpy="0 0 0" />
      <mass
        value="44.945" />
      <inertia
        ixx="0.18122"
        ixy="5.7883E-06"
        ixz="-0.0072268"
        iyy="0.52574"
        iyz="3.2086E-06"
        izz="0.4104" />
    </inertial>
    <visual>
      <origin
        xyz="0 0 0"
        rpy="0 0 0" />
      <geometry>
        <mesh
          filename="package://SMART NS 12-1,85 ARC_040128.SLDASM/meshes/Link4.STL" />
      </geometry>
      <material
        name="">
        <color
          rgba="1 0 0 1" />
      </material>
    </visual>
    <collision>
      <origin
        xyz="0 0 0"
        rpy="0 0 0" />
      <geometry>
        <mesh
          filename="package://SMART NS 12-1,85 ARC_040128.SLDASM/meshes/Link4.STL" />
      </geometry>
    </collision>
  </link>
  <joint
    name="Ax4"
    type="continuous">
    <origin
      xyz="-0.238 0.185 0.101"
      rpy="0 0 0" />
    <parent
      link="Link3" />
    <child
      link="Link4" />
    <axis
      xyz="1 0 0" />
  </joint>
  <link
    name="Link5">
    <inertial>
      <origin
        xyz="-0.0417593366585804 2.64362911670535E-05 -0.00106287346441888"
        rpy="0 0 0" />
      <mass
        value="4.38982627500557" />
      <inertia
        ixx="0.00326590350076518"
        ixy="-4.76651191579561E-06"
        ixz="0.000157386056054739"
        iyy="0.00776211709964979"
        iyz="4.21608948038967E-06"
        izz="0.00768408248717458" />
    </inertial>
    <visual>
      <origin
        xyz="0 0 0"
        rpy="0 0 0" />
      <geometry>
        <mesh
          filename="package://SMART NS 12-1,85 ARC_040128.SLDASM/meshes/Link5.STL" />
      </geometry>
      <material
        name="">
        <color
          rgba="0.501960784313725 0.501960784313725 0.501960784313725 1" />
      </material>
    </visual>
    <collision>
      <origin
        xyz="0 0 0"
        rpy="0 0 0" />
      <geometry>
        <mesh
          filename="package://SMART NS 12-1,85 ARC_040128.SLDASM/meshes/Link5.STL" />
      </geometry>
    </collision>
  </link>
  <joint
    name="Ax5"
    type="continuous">
    <origin
      xyz="-0.592 0 0"
      rpy="0 0 0" />
    <parent
      link="Link4" />
    <child
      link="Link5" />
    <axis
      xyz="0 0 1" />
  </joint>
  <link
    name="Link6">
    <inertial>
      <origin
        xyz="-0.0148549427534164 -0.00130113394450015 3.25513187997979E-05"
        rpy="0 0 0" />
      <mass
        value="0.721881062345406" />
      <inertia
        ixx="0.000738951655222946"
        ixy="2.55084893274034E-06"
        ixz="-2.78751313119689E-07"
        iyy="0.000418815751052622"
        iyz="-3.05758419040228E-08"
        izz="0.000386595590201194" />
    </inertial>
    <visual>
      <origin
        xyz="0 0 0"
        rpy="0 0 0" />
      <geometry>
        <mesh
          filename="package://SMART NS 12-1,85 ARC_040128.SLDASM/meshes/Link6.STL" />
      </geometry>
      <material
        name="">
        <color
          rgba="0.250980392156863 0.250980392156863 0.250980392156863 1" />
      </material>
    </visual>
    <collision>
      <origin
        xyz="0 0 0"
        rpy="0 0 0" />
      <geometry>
        <mesh
          filename="package://SMART NS 12-1,85 ARC_040128.SLDASM/meshes/Link6.STL" />
      </geometry>
    </collision>
  </link>
  <joint
    name="Ax6"
    type="continuous">
    <origin
      xyz="-0.094 0 0"
      rpy="0 0 0" />
    <parent
      link="Link5" />
    <child
      link="Link6" />
    <axis
      xyz="1 0 0" />
  </joint>
</robot>